<?xml version="1.0"?>
<robot name="simple_bot">
	<material name="rubber">
		<color rgba="0 0 0 1"/>
	</material>
	<material name="steel">
		<color rgba="0.75 0.75 0.75 1"/>
	</material>

	<link name="base_link">
		<visual>
			<geometry>
				<box size= "0.3 0.8 0.3"/>
			</geometry>
			<material name="steel"/>
		</visual>
		<collision>
			<geometry>
				<box size= "0.3 0.8 0.3"/>
			</geometry>
		</collision>
		<inertial>
			<mass value="1"/>
			<inertia ixx="0.0608333333"  iyy="0.015" izz="0.0608333333" ixy="0" ixz="0" iyz="0"/>
		</inertial>
	</link>
	<link name="wheel_1">
		<visual>
			<geometry>
				<cylinder length="0.01" radius="0.2" />
			</geometry>
			<material name="rubber"/>
			<origin rpy="0 1.57 0" xyz="0.005 0 0"/>
		</visual>
		<collision>
			<geometry>
				<cylinder length="0.01" radius="0.2"/>
			</geometry>
		</collision>
		<inertial>
			<mass value="1"/>
			<inertia ixx="0.02"  iyy="0.01" izz="0.01" ixy="0" ixz="0" iyz="0"/>
		</inertial>
	</link> 
<!--	<joint name="Wheel1ToBase" type="fixed">
		<parent link="base_link"/>
		<child link="wheel_1"/>
		<origin xyz="0.15 0.4 0"/>
	</joint> -->
	<joint name="Wheel1ToBaseMove" type="continuous">
		<parent link="base_link"/>
		<child link="wheel_1"/>
		<axis xyz="1 0 0"/>
		<origin xyz="0.15 0.4 0"/>
	</joint>
	<link name="wheel_2">
		<visual>
			<geometry>
				<cylinder length="0.01" radius="0.2" />
			</geometry>
			<material name="rubber"/>
			<origin rpy="0 1.57 0" xyz="-0.005 0 0"/>
		</visual>
		<collision>
			<geometry>
				<cylinder length="0.01" radius="0.2"/>
			</geometry>
		</collision>
		<inertial>
			<mass value="1"/>
			<inertia ixx="0.02"  iyy="0.01" izz="0.01" ixy="0" ixz="0" iyz="0"/>
		</inertial>
	</link> 
<!--	<joint name="Wheel2ToBase" type="fixed">
		<parent link="base_link"/>
		<child link="wheel_2"/>
		<origin xyz="-0.15 0.4 0"/>
	</joint> -->
	<joint name="Wheel2ToBaseMove" type="continuous">
		<parent link="base_link"/>
		<child link="wheel_2"/>
		<axis xyz="1 0 0"/>    
		<origin xyz="-0.15 0.4 0"/>
	</joint>
	<link name="wheel_3">
		<visual>
			<geometry>
				<cylinder length="0.01" radius="0.2" />
			</geometry>
			<material name="rubber"/>
			<origin rpy="0 1.57 0" xyz="0.005 0 0"/>
		</visual>
		<collision>
			<geometry>
				<cylinder length="0.01" radius="0.2"/>
			</geometry>
		</collision>
		<inertial>
			<mass value="1"/>
			<inertia ixx="0.02"  iyy="0.01" izz="0.01" ixy="0" ixz="0" iyz="0"/>
		</inertial>
	</link> 
<!--	<joint name="Wheel3ToBase" type="fixed">
		<parent link="base_link"/>
		<child link="wheel_3"/>
		<origin xyz="0.15 -0.4 0"/>
	</joint> -->
	<joint name="Wheel3ToBaseMove" type="continuous">
		<parent link="base_link"/>
		<child link="wheel_3"/>
		<axis xyz="1 0 0"/>
		<origin xyz="0.15 -0.4 0"/>
	</joint>
	<link name="wheel_4">
		<visual>
			<geometry>
				<cylinder length="0.01" radius="0.2" />
			</geometry>
			<material name="rubber"/>
			<origin rpy="0 1.57 0" xyz="-0.005 0 0"/>
		</visual>
		<collision>
			<geometry>
				<cylinder length="0.01" radius="0.2"/>
			</geometry>
		</collision>
		<inertial>
			<mass value="1"/>
			<inertia ixx="0.02"  iyy="0.01" izz="0.01" ixy="0" ixz="0" iyz="0"/>
		</inertial>
	</link> 
<!--	<joint name="Wheel4ToBase" type="fixed">
		<parent link="base_link"/>
		<child link="wheel_4"/>
		<origin xyz="-0.15 -0.4 0"/>
	</joint>-->
	<joint name="Wheel4ToBaseMove" type="continuous">
		<parent link="base_link"/>
		<child link="wheel_4"/>
		<axis xyz="1 0 0"/>
		<origin xyz="-0.15 -0.4 0"/>
	</joint>
	<gazebo>
		<plugin name="gazebo_ros_control" filename="libgazebo_ros_control.so">
			<robotNamespace>/</robotNamespace>
		</plugin>
	</gazebo>
</robot>
